<?xml version='1.0' encoding='utf-8'?>
<robot name="dvrk_psm">
  <!--Generated by scripts/rebuild_super_psm_from_dvrk_xacro.py from dVRK Classic PSM1 xacro.-->
  <!--Mimic tags are exported to psm_mimic_map.json and removed from URDF for parser compatibility.-->
  <material name="DaVinciWhite">
    <color rgba="1.0 1.0 1.0 1" />
  </material>
  <material name="DaVinciLightGray">
    <color rgba="0.8 0.8 0.8 1" />
  </material>
  <material name="DaVinciMedGray">
    <color rgba="0.6 0.6 0.6 1" />
  </material>
  <material name="DaVinciDarkGray">
    <color rgba="0.4 0.4 0.4 1" />
  </material>
  <material name="DaVinciRed">
    <color rgba="0.5 0.4 0.4 1" />
  </material>
  <material name="DaVinciGreen">
    <color rgba="0.4 0.5 0.4 1" />
  </material>
  <material name="DaVinciBlue">
    <color rgba="0.4 0.4 0.5 1" />
  </material>
  <link name="world" />
  <joint name="fixed" type="fixed">
    <parent link="world" />
    <child link="PSM1_psm_base_link" />
    <origin rpy="0.733342957 0.492181364 2.02256874" xyz="0.0994293715 -0.0484231708 0.0993431732" />
  </joint>
  <link name="PSM1_psm_base_link">
    <visual>
      <origin rpy="1.5708 0 3.1416" xyz="0.039 -0.40788 -0.07879" />
      <geometry>
        <mesh filename="meshes/psm_base.stl" />
      </geometry>
    </visual>
    <collision>
      <origin rpy="1.5708 0 3.1416" xyz="0.039 -0.40788 -0.07879" />
      <geometry>
        <mesh filename="meshes/psm_base.stl" />
      </geometry>
    </collision>
    <inertial>
      <mass value="0.001" />
      <inertia ixx="1e-8" ixy="0" ixz="0" iyy="1e-8" iyz="0" izz="1e-8" />
    </inertial>
  </link>
  <joint name="yaw" type="revolute">
    <parent link="PSM1_psm_base_link" />
    <child link="PSM1_outer_yaw_link" />
    <axis xyz="0 0 1" />
    <origin rpy="0 -1.5708 1.5708" xyz="0.0 0.0 0.0" />
    <limit effort="1000" lower="-1.5707" upper="1.5707" velocity=".4" />
  </joint>
  <link name="PSM1_outer_yaw_link">
    <visual>
      <origin rpy="3.1416 0 1.5708" xyz="0.0125 0 0.5265" />
      <geometry>
        <mesh filename="meshes/outer_yaw.stl" />
      </geometry>
    </visual>
    <collision>
      <origin rpy="3.1416 0 1.5708" xyz="0.0125 0 0.5265" />
      <geometry>
        <mesh filename="meshes/outer_yaw.stl" />
      </geometry>
    </collision>
    <inertial>
      <mass value="0.001" />
      <inertia ixx="1e-8" ixy="0" ixz="0" iyy="1e-8" iyz="0" izz="1e-8" />
    </inertial>
  </link>
  <joint name="pitch" type="revolute">
    <parent link="PSM1_outer_yaw_link" />
    <child link="PSM1_outer_pitch_link" />
    <axis xyz="0 0 1" />
    <origin rpy="-1.5708 -1.5708 0" xyz="0 0 0" />
    <limit effort="1000" lower="-0.7854" upper="0.7854" velocity=".4" />
  </joint>
  <link name="PSM1_outer_pitch_link">
    <collision>
      <origin rpy="0 0 0" xyz="0 0 0" />
      <geometry>
        <box size="0.001 0.001 0.001" />
      </geometry>
    </collision>
    <inertial>
      <mass value="0.001" />
      <inertia ixx="1e-8" ixy="0" ixz="0" iyy="1e-8" iyz="0" izz="1e-8" />
    </inertial>
  </link>
  <joint name="pitch_1" type="continuous">
    <parent link="PSM1_outer_yaw_link" />
    <child link="PSM1_outer_pitch_back_link" />
    <axis xyz="0 0 1" />
    <origin rpy="-1.5708 -1.5708 0" xyz="0 0.0295 0.5185" />
  </joint>
  <link name="PSM1_outer_pitch_back_link">
    <visual>
      <origin rpy="0 0 -0.27129" xyz="0 0 0" />
      <geometry>
        <mesh filename="meshes/outer_pitch_back.stl" />
      </geometry>
    </visual>
    <collision>
      <origin rpy="0 0 -0.27129" xyz="0 0 0" />
      <geometry>
        <mesh filename="meshes/outer_pitch_back.stl" />
      </geometry>
    </collision>
    <inertial>
      <mass value="0.001" />
      <inertia ixx="1e-8" ixy="0" ixz="0" iyy="1e-8" iyz="0" izz="1e-8" />
    </inertial>
  </link>
  <joint name="pitch_2" type="continuous">
    <parent link="PSM1_outer_yaw_link" />
    <child link="PSM1_outer_pitch_front_link" />
    <axis xyz="0 0 1" />
    <origin rpy="-1.5708 -1.5708 0" xyz="0 0.0295 0.4285" />
  </joint>
  <link name="PSM1_outer_pitch_front_link">
    <visual>
      <origin rpy="0 0 -0.27129" xyz="0 0 0" />
      <geometry>
        <mesh filename="meshes/outer_pitch_front.stl" />
      </geometry>
    </visual>
    <collision>
      <origin rpy="0 0 -0.27129" xyz="0 0 0" />
      <geometry>
        <mesh filename="meshes/outer_pitch_front.stl" />
      </geometry>
    </collision>
    <inertial>
      <mass value="0.001" />
      <inertia ixx="1e-8" ixy="0" ixz="0" iyy="1e-8" iyz="0" izz="1e-8" />
    </inertial>
  </link>
  <joint name="pitch_3" type="continuous">
    <parent link="PSM1_outer_pitch_back_link" />
    <child link="PSM1_outer_pitch_bottom_link" />
    <axis xyz="0 0 1" />
    <origin rpy="0 0 0" xyz="0.04178 0.15007 -0.0137" />
  </joint>
  <link name="PSM1_outer_pitch_bottom_link">
    <visual>
      <origin rpy="0 -1.5708 0" xyz="0.009 0 0" />
      <geometry>
        <mesh filename="meshes/outer_pitch_bottom.stl" />
      </geometry>
    </visual>
    <collision>
      <origin rpy="0 -1.5708 0" xyz="0.009 0 0" />
      <geometry>
        <mesh filename="meshes/outer_pitch_bottom.stl" />
      </geometry>
    </collision>
    <inertial>
      <mass value="0.001" />
      <inertia ixx="1e-8" ixy="0" ixz="0" iyy="1e-8" iyz="0" izz="1e-8" />
    </inertial>
  </link>
  <joint name="pitch_4" type="continuous">
    <parent link="PSM1_outer_pitch_back_link" />
    <child link="PSM1_outer_pitch_top_link" />
    <axis xyz="0 0 1" />
    <origin rpy="0 0 0" xyz="0.04209 0.18695 -0.02412" />
  </joint>
  <link name="PSM1_outer_pitch_top_link">
    <visual>
      <origin rpy="0 -1.5708 0" xyz="0.009 0 0" />
      <geometry>
        <mesh filename="meshes/outer_pitch_top.stl" />
      </geometry>
    </visual>
    <collision>
      <origin rpy="0 -1.5708 0" xyz="0.009 0 0" />
      <geometry>
        <mesh filename="meshes/outer_pitch_top.stl" />
      </geometry>
    </collision>
    <inertial>
      <mass value="0.001" />
      <inertia ixx="1e-8" ixy="0" ixz="0" iyy="1e-8" iyz="0" izz="1e-8" />
    </inertial>
  </link>
  <joint name="pitch_5" type="continuous">
    <parent link="PSM1_outer_pitch_bottom_link" />
    <child link="PSM1_outer_insertion_link" />
    <axis xyz="0 0 1" />
    <origin rpy="0 0 0" xyz="-0.520 0 -0.0155" />
  </joint>
  <link name="PSM1_outer_insertion_link">
    <visual>
      <origin rpy="0 -1.5708 1.5708" xyz="0.02528 0.429 0" />
      <geometry>
        <mesh filename="meshes/outer_insertion.stl" />
      </geometry>
    </visual>
    <collision>
      <origin rpy="0 -1.5708 1.5708" xyz="0.02528 0.429 0" />
      <geometry>
        <mesh filename="meshes/outer_insertion.stl" />
      </geometry>
    </collision>
    <inertial>
      <mass value="0.001" />
      <inertia ixx="1e-8" ixy="0" ixz="0" iyy="1e-8" iyz="0" izz="1e-8" />
    </inertial>
  </link>
  <joint name="insertion" type="prismatic">
    <parent link="PSM1_outer_pitch_link" />
    <child link="PSM1_tool_main_link" />
    <axis xyz="0 0 1" />
    <origin rpy="1.5708 0 0" xyz="0 0.4318 0" />
    <limit effort="1000" lower="0" upper="0.240" velocity=".4" />
  </joint>
  <link name="PSM1_tool_main_link">
    <visual>
      <origin rpy="0 0 1.5708" xyz="0 0 0.041" />
      <geometry>
        <mesh filename="meshes/tool_main.stl" />
      </geometry>
    </visual>
    <collision>
      <origin rpy="0 0 1.5708" xyz="0 0 0.041" />
      <geometry>
        <mesh filename="meshes/tool_main.stl" />
      </geometry>
    </collision>
    <inertial>
      <mass value="0.001" />
      <inertia ixx="1e-8" ixy="0" ixz="0" iyy="1e-8" iyz="0" izz="1e-8" />
    </inertial>
  </link>
  <joint name="roll" type="revolute">
    <parent link="PSM1_tool_main_link" />
    <child link="PSM1_tool_wrist_link" />
    <axis xyz="0 0 1" />
    <origin rpy="0 0 0" xyz="0 0 0.4162" />
    <limit effort="1000" lower="-3.5" upper="3.5" velocity=".4" />
  </joint>
  <link name="PSM1_tool_wrist_link">
    <visual>
      <origin rpy="0 0 1.5708" xyz="0 0 -0.0091" />
      <geometry>
        <mesh filename="meshes/tool_wrist_link.stl" />
      </geometry>
    </visual>
    <collision>
      <origin rpy="0 0 1.5708" xyz="0 0 -0.0091" />
      <geometry>
        <mesh filename="meshes/tool_wrist_link.stl" />
      </geometry>
    </collision>
    <inertial>
      <mass value="0.001" />
      <inertia ixx="1e-8" ixy="0" ixz="0" iyy="1e-8" iyz="0" izz="1e-8" />
    </inertial>
  </link>
  <joint name="roll_shaft" type="fixed">
    <parent link="PSM1_tool_wrist_link" />
    <child link="PSM1_tool_wrist_shaft_link" />
    <axis xyz="0 0 1" />
    <origin rpy="0 0 0" xyz="0 0 0.0" />
  </joint>
  <link name="PSM1_tool_wrist_shaft_link">
    <visual>
      <origin rpy="1.5708 0 0" xyz="0 0.00401 0" />
      <geometry>
        <mesh filename="meshes/tool_wrist_shaft_link.stl" />
      </geometry>
    </visual>
    <collision>
      <origin rpy="1.5708 0 0" xyz="0 0.00401 0" />
      <geometry>
        <mesh filename="meshes/tool_wrist_shaft_link.stl" />
      </geometry>
    </collision>
    <inertial>
      <mass value="0.001" />
      <inertia ixx="1e-8" ixy="0" ixz="0" iyy="1e-8" iyz="0" izz="1e-8" />
    </inertial>
  </link>
  <joint name="wrist_pitch" type="revolute">
    <parent link="PSM1_tool_wrist_shaft_link" />
    <child link="PSM1_tool_wrist_sca_link" />
    <axis xyz="0 0 1" />
    <origin rpy="-1.5708 -1.5708 0" xyz="0 0 0" />
    <limit effort="1000" lower="-1.5707" upper="1.5707" velocity=".4" />
  </joint>
  <link name="PSM1_tool_wrist_sca_link">
    <visual>
      <origin rpy="1.5708 3.1416 0" xyz="0.0051 0.0032 0" />
      <geometry>
        <mesh filename="meshes/tool_wrist_sca_link.stl" />
      </geometry>
    </visual>
    <collision>
      <origin rpy="1.5708 3.1416 0" xyz="0.0051 0.0032 0" />
      <geometry>
        <mesh filename="meshes/tool_wrist_sca_link.stl" />
      </geometry>
    </collision>
    <inertial>
      <mass value="0.001" />
      <inertia ixx="1e-8" ixy="0" ixz="0" iyy="1e-8" iyz="0" izz="1e-8" />
    </inertial>
  </link>
  <joint name="wrist_yaw" type="revolute">
    <parent link="PSM1_tool_wrist_sca_link" />
    <child link="PSM1_tool_wrist_sca_shaft_link" />
    <axis xyz="0 0 1" />
    <origin rpy="-1.5708 -1.5708 0" xyz="0.0091 0 0" />
    <limit effort="1000" lower="-1.3963" upper="1.3963" velocity=".4" />
  </joint>
  <link name="PSM1_tool_wrist_sca_shaft_link">
    <visual>
      <origin rpy="0 0 0" xyz="0 -0.0002 -0.0025" />
      <geometry>
        <mesh filename="meshes/tool_wrist_sca_shaft_link.stl" />
      </geometry>
    </visual>
    <collision>
      <origin rpy="0 0 0" xyz="0 -0.0002 -0.0025" />
      <geometry>
        <mesh filename="meshes/tool_wrist_sca_shaft_link.stl" />
      </geometry>
    </collision>
    <inertial>
      <mass value="0.001" />
      <inertia ixx="1e-8" ixy="0" ixz="0" iyy="1e-8" iyz="0" izz="1e-8" />
    </inertial>
  </link>
  <joint name="jaw" type="revolute">
    <parent link="PSM1_tool_wrist_sca_shaft_link" />
    <child link="PSM1_tool_wrist_sca_ee_link_0" />
    <axis xyz="0 0 1" />
    <origin rpy="0 0 0" xyz="0 0 0" />
    <limit effort="1000" lower="-1.2" upper="1.6" velocity=".4" />
  </joint>
  <link name="PSM1_tool_wrist_sca_ee_link_0">
    <visual>
      <origin rpy="0 0 0" xyz="0 0 0" />
      <geometry>
        <box size="0 0 0" />
      </geometry>
    </visual>
    <collision>
      <origin rpy="0 0 0" xyz="0 0 0" />
      <geometry>
        <box size="0 0 0" />
      </geometry>
    </collision>
    <inertial>
      <mass value="0.001" />
      <inertia ixx="1e-8" ixy="0" ixz="0" iyy="1e-8" iyz="0" izz="1e-8" />
    </inertial>
  </link>
  <joint name="jaw_mimic_1" type="revolute">
    <parent link="PSM1_tool_wrist_sca_shaft_link" />
    <child link="PSM1_tool_wrist_sca_ee_link_1" />
    <axis xyz="0 0 1" />
    <origin rpy="0 0 0" xyz="0 0 0" />
    <limit effort="1000" lower="-1.5707" upper="1.5707" velocity=".4" />
  </joint>
  <link name="PSM1_tool_wrist_sca_ee_link_1">
    <visual>
      <origin rpy="0 0 0" xyz="0 0 0" />
      <geometry>
        <mesh filename="meshes/tool_wrist_sca_link_2.stl" />
      </geometry>
    </visual>
    <collision>
      <origin rpy="0 0 0" xyz="0 0 0" />
      <geometry>
        <mesh filename="meshes/tool_wrist_sca_link_2.stl" />
      </geometry>
    </collision>
    <inertial>
      <mass value="0.001" />
      <inertia ixx="1e-8" ixy="0" ixz="0" iyy="1e-8" iyz="0" izz="1e-8" />
    </inertial>
  </link>
  <joint name="jaw_mimic_2" type="revolute">
    <parent link="PSM1_tool_wrist_sca_shaft_link" />
    <child link="PSM1_tool_wrist_sca_ee_link_2" />
    <axis xyz="0 0 1" />
    <origin rpy="0 0 0" xyz="0 0 0" />
    <limit effort="1000" lower="-1.5707" upper="1.5707" velocity=".4" />
  </joint>
  <link name="PSM1_tool_wrist_sca_ee_link_2">
    <visual>
      <origin rpy="0 3.1516 0" xyz="0 0 0" />
      <geometry>
        <mesh filename="meshes/tool_wrist_sca_link_2.stl" />
      </geometry>
    </visual>
    <collision>
      <origin rpy="0 3.1516 0" xyz="0 0 0" />
      <geometry>
        <mesh filename="meshes/tool_wrist_sca_link_2.stl" />
      </geometry>
    </collision>
    <inertial>
      <mass value="0.001" />
      <inertia ixx="1e-8" ixy="0" ixz="0" iyy="1e-8" iyz="0" izz="1e-8" />
    </inertial>
  </link>
  <joint name="tool_tip" type="fixed">
    <parent link="PSM1_tool_wrist_sca_shaft_link" />
    <child link="PSM1_tool_tip_link" />
    <origin rpy="0 1.5707963267948966 1.5707963267948966" xyz="0 0.0102 0" />
  </joint>
  <link name="PSM1_tool_tip_link">
    <collision>
      <origin rpy="0 0 0" xyz="0 0 0" />
      <geometry>
        <sphere radius="0.001" />
      </geometry>
    </collision>
    <inertial>
      <mass value="0.001" />
      <inertia ixx="1e-8" ixy="0" ixz="0" iyy="1e-8" iyz="0" izz="1e-8" />
    </inertial>
  </link>
</robot>